2018-05-30 18:35:17,963 ERROR: Exception on /home [GET] [in /Users/brianli/Documents/Budget/venv/lib/python3.6/site-packages/flask/app.py:1761]
Traceback (most recent call last):
  File "/Users/brianli/Documents/Budget/venv/lib/python3.6/site-packages/flask/app.py", line 2292, in wsgi_app
    response = self.full_dispatch_request()
  File "/Users/brianli/Documents/Budget/venv/lib/python3.6/site-packages/flask/app.py", line 1815, in full_dispatch_request
    rv = self.handle_user_exception(e)
  File "/Users/brianli/Documents/Budget/venv/lib/python3.6/site-packages/flask/app.py", line 1718, in handle_user_exception
    reraise(exc_type, exc_value, tb)
  File "/Users/brianli/Documents/Budget/venv/lib/python3.6/site-packages/flask/_compat.py", line 35, in reraise
    raise value
  File "/Users/brianli/Documents/Budget/venv/lib/python3.6/site-packages/flask/app.py", line 1813, in full_dispatch_request
    rv = self.dispatch_request()
  File "/Users/brianli/Documents/Budget/venv/lib/python3.6/site-packages/flask/app.py", line 1799, in dispatch_request
    return self.view_functions[rule.endpoint](**req.view_args)
  File "/Users/brianli/Documents/Budget/venv/lib/python3.6/site-packages/flask_login/utils.py", line 261, in decorated_view
    return func(*args, **kwargs)
  File "/Users/brianli/Documents/Budget/app/routes.py", line 13, in home
    form = PostForm()
NameError: name 'PostForm' is not defined
2018-05-30 18:35:30,108 INFO: Microblog startup [in /Users/brianli/Documents/Budget/app/__init__.py:46]
2018-05-30 18:36:23,733 INFO: Microblog startup [in /Users/brianli/Documents/Budget/app/__init__.py:46]
2018-05-30 18:36:27,250 INFO: Microblog startup [in /Users/brianli/Documents/Budget/app/__init__.py:46]
2018-05-30 18:36:32,830 ERROR: Exception on /home [POST] [in /Users/brianli/Documents/Budget/venv/lib/python3.6/site-packages/flask/app.py:1761]
Traceback (most recent call last):
  File "/Users/brianli/Documents/Budget/venv/lib/python3.6/site-packages/flask/app.py", line 2292, in wsgi_app
    response = self.full_dispatch_request()
  File "/Users/brianli/Documents/Budget/venv/lib/python3.6/site-packages/flask/app.py", line 1815, in full_dispatch_request
    rv = self.handle_user_exception(e)
  File "/Users/brianli/Documents/Budget/venv/lib/python3.6/site-packages/flask/app.py", line 1718, in handle_user_exception
    reraise(exc_type, exc_value, tb)
  File "/Users/brianli/Documents/Budget/venv/lib/python3.6/site-packages/flask/_compat.py", line 35, in reraise
    raise value
  File "/Users/brianli/Documents/Budget/venv/lib/python3.6/site-packages/flask/app.py", line 1813, in full_dispatch_request
    rv = self.dispatch_request()
  File "/Users/brianli/Documents/Budget/venv/lib/python3.6/site-packages/flask/app.py", line 1799, in dispatch_request
    return self.view_functions[rule.endpoint](**req.view_args)
  File "/Users/brianli/Documents/Budget/venv/lib/python3.6/site-packages/flask_login/utils.py", line 261, in decorated_view
    return func(*args, **kwargs)
  File "/Users/brianli/Documents/Budget/app/routes.py", line 15, in home
    expense = Expense(type = form.type.data, amount = form.amount.data,
NameError: name 'Expense' is not defined
2018-05-30 18:37:02,195 INFO: Microblog startup [in /Users/brianli/Documents/Budget/app/__init__.py:46]
2018-05-30 18:37:07,825 ERROR: Exception on /home [GET] [in /Users/brianli/Documents/Budget/venv/lib/python3.6/site-packages/flask/app.py:1761]
Traceback (most recent call last):
  File "/Users/brianli/Documents/Budget/venv/lib/python3.6/site-packages/flask/app.py", line 2292, in wsgi_app
    response = self.full_dispatch_request()
  File "/Users/brianli/Documents/Budget/venv/lib/python3.6/site-packages/flask/app.py", line 1815, in full_dispatch_request
    rv = self.handle_user_exception(e)
  File "/Users/brianli/Documents/Budget/venv/lib/python3.6/site-packages/flask/app.py", line 1718, in handle_user_exception
    reraise(exc_type, exc_value, tb)
  File "/Users/brianli/Documents/Budget/venv/lib/python3.6/site-packages/flask/_compat.py", line 35, in reraise
    raise value
  File "/Users/brianli/Documents/Budget/venv/lib/python3.6/site-packages/flask/app.py", line 1813, in full_dispatch_request
    rv = self.dispatch_request()
  File "/Users/brianli/Documents/Budget/venv/lib/python3.6/site-packages/flask/app.py", line 1799, in dispatch_request
    return self.view_functions[rule.endpoint](**req.view_args)
  File "/Users/brianli/Documents/Budget/venv/lib/python3.6/site-packages/flask_login/utils.py", line 261, in decorated_view
    return func(*args, **kwargs)
  File "/Users/brianli/Documents/Budget/app/routes.py", line 21, in home
    expenses = current_user.posted_expenses().all()
  File "/Users/brianli/Documents/Budget/venv/lib/python3.6/site-packages/sqlalchemy/orm/query.py", line 2783, in all
    return list(self)
  File "/Users/brianli/Documents/Budget/venv/lib/python3.6/site-packages/sqlalchemy/orm/loading.py", line 98, in instances
    util.raise_from_cause(err)
  File "/Users/brianli/Documents/Budget/venv/lib/python3.6/site-packages/sqlalchemy/util/compat.py", line 203, in raise_from_cause
    reraise(type(exception), exception, tb=exc_tb, cause=cause)
  File "/Users/brianli/Documents/Budget/venv/lib/python3.6/site-packages/sqlalchemy/util/compat.py", line 187, in reraise
    raise value
  File "/Users/brianli/Documents/Budget/venv/lib/python3.6/site-packages/sqlalchemy/orm/loading.py", line 79, in instances
    rows = [proc(row) for row in fetch]
  File "/Users/brianli/Documents/Budget/venv/lib/python3.6/site-packages/sqlalchemy/orm/loading.py", line 79, in <listcomp>
    rows = [proc(row) for row in fetch]
  File "/Users/brianli/Documents/Budget/venv/lib/python3.6/site-packages/sqlalchemy/orm/loading.py", line 511, in _instance
    loaded_instance, populate_existing, populators)
  File "/Users/brianli/Documents/Budget/venv/lib/python3.6/site-packages/sqlalchemy/orm/loading.py", line 611, in _populate_full
    dict_[key] = getter(row)
TypeError: must be real number, not str
2018-05-30 18:38:35,451 INFO: Microblog startup [in /Users/brianli/Documents/Budget/app/__init__.py:46]
2018-05-30 18:38:37,093 ERROR: Exception on /home [GET] [in /Users/brianli/Documents/Budget/venv/lib/python3.6/site-packages/flask/app.py:1761]
Traceback (most recent call last):
  File "/Users/brianli/Documents/Budget/venv/lib/python3.6/site-packages/flask/app.py", line 2292, in wsgi_app
    response = self.full_dispatch_request()
  File "/Users/brianli/Documents/Budget/venv/lib/python3.6/site-packages/flask/app.py", line 1815, in full_dispatch_request
    rv = self.handle_user_exception(e)
  File "/Users/brianli/Documents/Budget/venv/lib/python3.6/site-packages/flask/app.py", line 1718, in handle_user_exception
    reraise(exc_type, exc_value, tb)
  File "/Users/brianli/Documents/Budget/venv/lib/python3.6/site-packages/flask/_compat.py", line 35, in reraise
    raise value
  File "/Users/brianli/Documents/Budget/venv/lib/python3.6/site-packages/flask/app.py", line 1813, in full_dispatch_request
    rv = self.dispatch_request()
  File "/Users/brianli/Documents/Budget/venv/lib/python3.6/site-packages/flask/app.py", line 1799, in dispatch_request
    return self.view_functions[rule.endpoint](**req.view_args)
  File "/Users/brianli/Documents/Budget/venv/lib/python3.6/site-packages/flask_login/utils.py", line 261, in decorated_view
    return func(*args, **kwargs)
  File "/Users/brianli/Documents/Budget/app/routes.py", line 21, in home
    expenses = current_user.posted_expenses().all()
  File "/Users/brianli/Documents/Budget/venv/lib/python3.6/site-packages/sqlalchemy/orm/query.py", line 2783, in all
    return list(self)
  File "/Users/brianli/Documents/Budget/venv/lib/python3.6/site-packages/sqlalchemy/orm/loading.py", line 98, in instances
    util.raise_from_cause(err)
  File "/Users/brianli/Documents/Budget/venv/lib/python3.6/site-packages/sqlalchemy/util/compat.py", line 203, in raise_from_cause
    reraise(type(exception), exception, tb=exc_tb, cause=cause)
  File "/Users/brianli/Documents/Budget/venv/lib/python3.6/site-packages/sqlalchemy/util/compat.py", line 187, in reraise
    raise value
  File "/Users/brianli/Documents/Budget/venv/lib/python3.6/site-packages/sqlalchemy/orm/loading.py", line 79, in instances
    rows = [proc(row) for row in fetch]
  File "/Users/brianli/Documents/Budget/venv/lib/python3.6/site-packages/sqlalchemy/orm/loading.py", line 79, in <listcomp>
    rows = [proc(row) for row in fetch]
  File "/Users/brianli/Documents/Budget/venv/lib/python3.6/site-packages/sqlalchemy/orm/loading.py", line 511, in _instance
    loaded_instance, populate_existing, populators)
  File "/Users/brianli/Documents/Budget/venv/lib/python3.6/site-packages/sqlalchemy/orm/loading.py", line 611, in _populate_full
    dict_[key] = getter(row)
TypeError: must be real number, not str
